Workbook

Sheet Dashboard
B2: US Regional Sales — Dashboard
B3: Source: Cleaned US Regional Sales dataset (Kaggle) | 2018–2020 | Currency: USD
B5: Total Revenue | C5: Total Profit | D5: Profit Margin | E5: Total Orders | F5: Avg Order→Delivery (days)
B6: ='KPI Summary'!B7 -> 73143380 | C6: ='KPI Summary'!F7 -> 21325311 | D6: ='KPI Summary'!H7 -> 0.2915549 | E6: ='KPI Summary'!B11 -> 7991 | F6: ='KPI Summary'!F15 -> 20.672882

Sheet Raw Data
A1: OrderNumber | B1: SalesChannel | C1: WarehouseCode | D1: ProcuredDate | E1: OrderDate | F1: ShipDate | G1: DeliveryDate | H1: CurrencyCode | I1: _SalesTeamID | J1: _CustomerID | K1: _StoreID | L1: _ProductID | M1: Order Quantity | N1: Discount Applied | O1: Unit Cost | P1: Unit Price | Q1: Revenue | R1: Cost | S1: Profit | T1: Margin % | U1: Order-to-Ship (Days) | V1: Ship-to-Delivery (Days) | W1: Order-to-Delivery (Days) | X1: Order Year | Y1: Order Month | Z1: Order Quarter
A2: SO - 000101 | B2: In-Store | C2: WARE-UHY1004 | D2: 43100 | E2: 43251 | F2: 43265 | G2: 43270 | H2: USD | I2: 6 | J2: 15 | K2: 259 | L2: 12 | M2: 5 | N2: 0.075 | O2: 1001.18 | P2: 1963.1 | Q2: =M2*P2*(1-N2) -> 9079.3375 | R2: =M2*O2 -> 5005.9 | S2: =Q2-R2 -> 4073.4375 | T2: =IFERROR(S2/Q2,0) -> 0.4486492 | U2: =F2-E2 -> 14 | V2: =G2-F2 -> 5 | W2: =G2-E2 -> 19 | X2: =YEAR(E2) -> 2018 | Y2: =TEXT(E2,"yyyy-mm") -> 2018-05 | Z2: ="Q"&ROUNDUP(MONTH(E2)/3,0)&"-"&YEAR(E2) -> Q2-2018
A3: SO - 000102 | B3: Online | C3: WARE-NMK1003 | D3: 43100 | E3: 43251 | F3: 43273 | G3: 43283 | H3: USD | I3: 14 | J3: 20 | K3: 196 | L3: 27 | M3: 3 | N3: 0.075 | O3: 3348.66 | P3: 3939.6 | Q3: =M3*P3*(1-N3) -> 10932.39 | R3: =M3*O3 -> 10045.98 | S3: =Q3-R3 -> 886.41 | T3: =IFERROR(S3/Q3,0) -> 0.081081081 | U3: =F3-E3 -> 22 | V3: =G3-F3 -> 10 | W3: =G3-E3 -> 32 | X3: =YEAR(E3) -> 2018 | Y3: =TEXT(E3,"yyyy-mm") -> 2018-05 | Z3: ="Q"&ROUNDUP(MONTH(E3)/3,0)&"-"&YEAR(E3) -> Q2-2018
A4: SO - 000103 | B4: Distributor | C4: WARE-UHY1004 | D4: 43100 | E4: 43251 | F4: 43272 | G4: 43282 | H4: USD | I4: 21 | J4: 16 | K4: 213 | L4: 16 | M4: 1 | N4: 0.05 | O4: 781.22 | P4: 1775.5 | Q4: =M4*P4*(1-N4) -> 1686.725 | R4: =M4*O4 -> 781.22 | S4: =Q4-R4 -> 905.505 | T4: =IFERROR(S4/Q4,0) -> 0.53684211 | U4: =F4-E4 -> 21 | V4: =G4-F4 -> 10 | W4: =G4-E4 -> 31 | X4: =YEAR(E4) -> 2018 | Y4: =TEXT(E4,"yyyy-mm") -> 2018-05 | Z4: ="Q"&ROUNDUP(MONTH(E4)/3,0)&"-"&YEAR(E4) -> Q2-2018
A5: SO - 000104 | B5: Wholesale | C5: WARE-NMK1003 | D5: 43100 | E5: 43251 | F5: 43253 | G5: 43258 | H5: USD | I5: 28 | J5: 48 | K5: 107 | L5: 23 | M5: 8 | N5: 0.075 | O5: 1464.69 | P5: 2324.9 | Q5: =M5*P5*(1-N5) -> 17204.26 | R5: =M5*O5 -> 11717.52 | S5: =Q5-R5 -> 5486.74 | T5: =IFERROR(S5/Q5,0) -> 0.31891752 | U5: =F5-E5 -> 2 | V5: =G5-F5 -> 5 | W5: =G5-E5 -> 7 | X5: =YEAR(E5) -> 2018 | Y5: =TEXT(E5,"yyyy-mm") -> 2018-05 | Z5: ="Q"&ROUNDUP(MONTH(E5)/3,0)&"-"&YEAR(E5) -> Q2-2018
A6: SO - 000105 | B6: Distributor | C6: WARE-NMK1003 | D6: 43200 | E6: 43251 | F6: 43267 | G6: 43277 | H6: USD | I6: 22 | J6: 49 | K6: 111 | L6: 26 | M6: 8 | N6: 0.1 | O6: 1476.14 | P6: 1822.4 | Q6: =M6*P6*(1-N6) -> 13121.28 | R6: =M6*O6 -> 11809.12 | S6: =Q6-R6 -> 1312.16 | T6: =IFERROR(S6/Q6,0) -> 0.10000244 | U6: =F6-E6 -> 16 | V6: =G6-F6 -> 10 | W6: =G6-E6 -> 26 | X6: =YEAR(E6) -> 2018 | Y6: =TEXT(E6,"yyyy-mm") -> 2018-05 | Z6: ="Q"&ROUNDUP(MONTH(E6)/3,0)&"-"&YEAR(E6) -> Q2-2018
A7: SO - 000106 | B7: Online | C7: WARE-PUJ1005 | D7: 43100 | E7: 43251 | F7: 43259 | G7: 43264 | H7: USD | I7: 12 | J7: 21 | K7: 285 | L7: 1 | M7: 5 | N7: 0.05 | O7: 446.56 | P7: 1038.5 | Q7: =M7*P7*(1-N7) -> 4932.875 | R7: =M7*O7 -> 2232.8 | S7: =Q7-R7 -> 2700.075 | T7: =IFERROR(S7/Q7,0) -> 0.54736335 | U7: =F7-E7 -> 8 | V7: =G7-F7 -> 5 | W7: =G7-E7 -> 13 | X7: =YEAR(E7) -> 2018 | Y7: =TEXT(E7,"yyyy-mm") -> 2018-05 | Z7: ="Q"&ROUNDUP(MONTH(E7)/3,0)&"-"&YEAR(E7) -> Q2-2018
A8: SO - 000107 | B8: In-Store | C8: WARE-XYS1001 | D8: 43100 | E8: 43251 | F8: 43259 | G8: 43265 | H8: USD | I8: 10 | J8: 14 | K8: 6 | L8: 5 | M8: 4 | N8: 0.15 | O8: 536.67 | P8: 1192.6 | Q8: =M8*P8*(1-N8) -> 4054.84 | R8: =M8*O8 -> 2146.68 | S8: =Q8-R8 -> 1908.16 | T8: =IFERROR(S8/Q8,0) -> 0.47058824 | U8: =F8-E8 -> 8 | V8: =G8-F8 -> 6 | W8: =G8-E8 -> 14 | X8: =YEAR(E8) -> 2018 | Y8: =TEXT(E8,"yyyy-mm") -> 2018-05 | Z8: ="Q"&ROUNDUP(MONTH(E8)/3,0)&"-"&YEAR(E8) -> Q2-2018
A9: SO - 000108 | B9: In-Store | C9: WARE-PUJ1005 | D9: 43200 | E9: 43251 | F9: 43277 | G9: 43282 | H9: USD | I9: 6 | J9: 9 | K9: 280 | L9: 46 | M9: 5 | N9: 0.05 | O9: 1525.19 | P9: 1815.7 | Q9: =M9*P9*(1-N9) -> 8624.575 | R9: =M9*O9 -> 7625.95 | S9: =Q9-R9 -> 998.625 | T9: =IFERROR(S9/Q9,0) -> 0.11578831 | U9: =F9-E9 -> 26 | V9: =G9-F9 -> 5 | W9: =G9-E9 -> 31 | X9: =YEAR(E9) -> 2018 | Y9: =TEXT(E9,"yyyy-mm") -> 2018-05 | Z9: ="Q"&ROUNDUP(MONTH(E9)/3,0)&"-"&YEAR(E9) -> Q2-2018
A10: SO - 000109 | B10: In-Store | C10: WARE-PUJ1005 | D10: 43100 | E10: 43252 | F10: 43267 | G10: 43272 | H10: USD | I10: 4 | J10: 9 | K10: 299 | L10: 47 | M10: 4 | N10: 0.3 | O10: 2211.2 | P10: 3879.3 | Q10: =M10*P10*(1-N10) -> 10862.04 | R10: =M10*O10 -> 8844.8 | S10: =Q10-R10 -> 2017.24 | T10: =IFERROR(S10/Q10,0) -> 0.18571465 | U10: =F10-E10 -> 15 | V10: =G10-F10 -> 5 | W10: =G10-E10 -> 20 | X10: =YEAR(E10) -> 2018 | Y10: =TEXT(E10,"yyyy-mm") -> 2018-06 | Z10: ="Q"&ROUNDUP(MONTH(E10)/3,0)&"-"&YEAR(E10) -> Q2-2018
A11: SO - 000110 | B11: In-Store | C11: WARE-UHY1004 | D11: 43100 | E11: 43252 | F11: 43280 | G11: 43282 | H11: USD | I11: 10 | J11: 33 | K11: 261 | L11: 13 | M11: 8 | N11: 0.05 | O11: 1212.97 | P11: 1956.4 | Q11: =M11*P11*(1-N11) -> 14868.64 | R11: =M11*O11 -> 9703.76 | S11: =Q11-R11 -> 5164.88 | T11: =IFERROR(S11/Q11,0) -> 0.34736734 | U11: =F11-E11 -> 28 | V11: =G11-F11 -> 2 | W11: =G11-E11 -> 30 | X11: =YEAR(E11) -> 2018 | Y11: =TEXT(E11,"yyyy-mm") -> 2018-06 | Z11: ="Q"&ROUNDUP(MONTH(E11)/3,0)&"-"&YEAR(E11) -> Q2-2018
A12: SO - 000111 | B12: Distributor | C12: WARE-XYS1001 | D12: 43100 | E12: 43252 | F12: 43266 | G12: 43271 | H12: USD | I12: 23 | J12: 21 | K12: 17 | L12: 38 | M12: 6 | N12: 0.1 | O12: 124.62 | P12: 201 | Q12: =M12*P12*(1-N12) -> 1085.4 | R12: =M12*O12 -> 747.72 | S12: =Q12-R12 -> 337.68 | T12: =IFERROR(S12/Q12,0) -> 0.31111111 | U12: =F12-E12 -> 14 | V12: =G12-F12 -> 5 | W12: =G12-E12 -> 19 | X12: =YEAR(E12) -> 2018 | Y12: =TEXT(E12,"yyyy-mm") -> 2018-06 | Z12: ="Q"&ROUNDUP(MONTH(E12)/3,0)&"-"&YEAR(E12) -> Q2-2018
A13: SO - 000112 | B13: In-Store | C13: WARE-NMK1003 | D13: 43200 | E13: 43252 | F13: 43258 | G13: 43268 | H13: USD | I13: 10 | J13: 21 | K13: 152 | L13: 40 | M13: 5 | N13: 0.15 | O13: 2762.28 | P13: 6277.9 | Q13: =M13*P13*(1-N13) -> 26681.075 | R13: =M13*O13 -> 13811.4 | S13: =Q13-R13 -> 12869.675 | T13: =IFERROR(S13/Q13,0) -> 0.48235219 | U13: =F13-E13 -> 6 | V13: =G13-F13 -> 10 | W13: =G13-E13 -> 16 | X13: =YEAR(E13) -> 2018 | Y13: =TEXT(E13,"yyyy-mm") -> 2018-06 | Z13: ="Q"&ROUNDUP(MONTH(E13)/3,0)&"-"&YEAR(E13) -> Q2-2018
... A7992: SO - 0008091 | B7992: In-Store | C7992: WARE-UHY1004 | D7992: 44100 | E7992: 44195 | F7992: 44209 | G7992: 44215 | H7992: USD | I7992: 6 | J7992: 41 | K7992: 237 | L7992: 43 | M7992: 5 | N7992: 0.075 | O7992: 1370.82 | P7992: 2211 | Q7992: =M7992*P7992*(1-N7992) -> 10225.875 | R7992: =M7992*O7992 -> 6854.1 | S7992: =Q7992-R7992 -> 3371.775 | T7992: =IFERROR(S7992/Q7992,0) -> 0.32972973 | U7992: =F7992-E7992 -> 14 | V7992: =G7992-F7992 -> 6 | W7992: =G7992-E7992 -> 20 | X7992: =YEAR(E7992) -> 2020 | Y7992: =TEXT(E7992,"yyyy-mm") -> 2020-12 | Z7992: ="Q"&ROUNDUP(MONTH(E7992)/3,0)&"-"&YEAR(E7992) -> Q4-2020

Sheet KPI Summary
B2: US Regional Sales — Executive KPI Summary
B3: All figures calculated dynamically from Raw Data (2018–2020)
B6: Total Revenue | D6: Total Cost | F6: Total Profit | H6: Overall Profit Margin
B7: =SUM('Raw Data'!Q2:Q7992) -> 73143380 | D7: =SUM('Raw Data'!R2:R7992) -> 51818069 | F7: =B7-D7 -> 21325311 | H7: =F7/B7 -> 0.2915549
B10: Total Orders | D10: Total Units Sold | F10: Avg Revenue / Order | H10: Avg Discount Applied
B11: =COUNTA('Raw Data'!A2:A7992) -> 7991 | D11: =SUM('Raw Data'!M2:M7992) -> 36162 | F11: =B7/B11 -> 9153.2198 | H11: =AVERAGE('Raw Data'!N2:N7992) -> 0.11439432
B14: Avg Order→Ship (days) | D14: Avg Ship→Delivery (days) | F14: Avg Order→Delivery (days) | H14: Revenue Lost to Discounts
B15: =AVERAGE('Raw Data'!U2:U7992) -> 15.16894 | D15: =AVERAGE('Raw Data'!V2:V7992) -> 5.5039419 | F15: =AVERAGE('Raw Data'!W2:W7992) -> 20.672882 | H15: =SUMPRODUCT('Raw Data'!M2:M7992*'Raw Data'!P2:P7992*'Raw Data'!N2:N7992) -> 9549346.9
B18: Note: "Regional" performance in this workbook is proxied by Warehouse location, since the source data
B19: does not include an explicit region/state field beyond the 6 warehouse codes. See "Regional Analysis" tab.

Sheet Channel Analysis
B2: Sales Channel Performance
B3: Which sales channel drives the most revenue?
B5: Sales Channel | C5: Orders | D5: Units Sold | E5: Revenue | F5: Cost | G5: Profit | H5: Margin % | I5: % of Total Revenue
B6: Distributor | C6: =COUNTIF('Raw Data'!$B$2:$B$7992,$B6) -> 1375 | D6: =SUMIF('Raw Data'!$B$2:$B$7992,$B6,'Raw Data'!$M$2:$M$7992) -> 6287 | E6: =SUMIF('Raw Data'!$B$2:$B$7992,$B6,'Raw Data'!$Q$2:$Q$7992) -> 13169148 | F6: =SUMIF('Raw Data'!$B$2:$B$7992,$B6,'Raw Data'!$R$2:$R$7992) -> 9281250.3 | G6: =E6-F6 -> 3887897.4 | H6: =IFERROR(G6/E6,0) -> 0.29522772 | I6: =E6/SUM($E$6:$E$9) -> 0.18004565
B7: In-Store | C7: =COUNTIF('Raw Data'!$B$2:$B$7992,$B7) -> 3298 | D7: =SUMIF('Raw Data'!$B$2:$B$7992,$B7,'Raw Data'!$M$2:$M$7992) -> 14878 | E7: =SUMIF('Raw Data'!$B$2:$B$7992,$B7,'Raw Data'!$Q$2:$Q$7992) -> 30102905 | F7: =SUMIF('Raw Data'!$B$2:$B$7992,$B7,'Raw Data'!$R$2:$R$7992) -> 21305051 | G7: =E7-F7 -> 8797853.2 | H7: =IFERROR(G7/E7,0) -> 0.29225928 | I7: =E7/SUM($E$6:$E$9) -> 0.41156021
B8: Online | C8: =COUNTIF('Raw Data'!$B$2:$B$7992,$B8) -> 2425 | D8: =SUMIF('Raw Data'!$B$2:$B$7992,$B8,'Raw Data'!$M$2:$M$7992) -> 10897 | E8: =SUMIF('Raw Data'!$B$2:$B$7992,$B8,'Raw Data'!$Q$2:$Q$7992) -> 21698559 | F8: =SUMIF('Raw Data'!$B$2:$B$7992,$B8,'Raw Data'!$R$2:$R$7992) -> 15531743 | G8: =E8-F8 -> 6166815.7 | H8: =IFERROR(G8/E8,0) -> 0.28420393 | I8: =E8/SUM($E$6:$E$9) -> 0.29665786
B9: Wholesale | C9: =COUNTIF('Raw Data'!$B$2:$B$7992,$B9) -> 893 | D9: =SUMIF('Raw Data'!$B$2:$B$7992,$B9,'Raw Data'!$M$2:$M$7992) -> 4100 | E9: =SUMIF('Raw Data'!$B$2:$B$7992,$B9,'Raw Data'!$Q$2:$Q$7992) -> 8172768.5 | F9: =SUMIF('Raw Data'!$B$2:$B$7992,$B9,'Raw Data'!$R$2:$R$7992) -> 5700024 | G9: =E9-F9 -> 2472744.5 | H9: =IFERROR(G9/E9,0) -> 0.30255898 | I9: =E9/SUM($E$6:$E$9) -> 0.11173627
B10: Total | C10: =SUM(C6:C9) -> 7991 | D10: =SUM(D6:D9) -> 36162 | E10: =SUM(E6:E9) -> 73143380 | F10: =SUM(F6:F9) -> 51818069 | G10: =SUM(G6:G9) -> 21325311 | H10: =IFERROR(G10/E10,0) -> 0.2915549 | I10: =SUM(I6:I9) -> 1

Sheet Product Analysis
B2: Product Performance (All 47 Products)
B3: Which products sell the most units vs. generate the most revenue vs. highest margin?
B5: Product ID | C5: Orders | D5: Units Sold | E5: Revenue | F5: Cost | G5: Profit | H5: Margin % | J5: Top 10 Products by Revenue
B6: 1 | C6: =COUNTIF('Raw Data'!$L$2:$L$7992,$B6) -> 162 | D6: =SUMIF('Raw Data'!$L$2:$L$7992,$B6,'Raw Data'!$M$2:$M$7992) -> 681 | E6: =SUMIF('Raw Data'!$L$2:$L$7992,$B6,'Raw Data'!$Q$2:$Q$7992) -> 1269278.3 | F6: =SUMIF('Raw Data'!$L$2:$L$7992,$B6,'Raw Data'!$R$2:$R$7992) -> 885425.71 | G6: =E6-F6 -> 383852.61 | H6: =IFERROR(G6/E6,0) -> 0.302418 | J6: Rank | K6: Product ID | L6: Revenue
B7: 2 | C7: =COUNTIF('Raw Data'!$L$2:$L$7992,$B7) -> 173 | D7: =SUMIF('Raw Data'!$L$2:$L$7992,$B7,'Raw Data'!$M$2:$M$7992) -> 819 | E7: =SUMIF('Raw Data'!$L$2:$L$7992,$B7,'Raw Data'!$Q$2:$Q$7992) -> 1775222.3 | F7: =SUMIF('Raw Data'!$L$2:$L$7992,$B7,'Raw Data'!$R$2:$R$7992) -> 1222038.6 | G7: =E7-F7 -> 553183.72 | H7: =IFERROR(G7/E7,0) -> 0.31161378 | J7: 1 | K7: =INDEX($B$6:$B$52,MATCH(LARGE($E$6:$E$52,J7),$E$6:$E$52,0)) -> 23 | L7: =LARGE($E$6:$E$52,J7) -> 2101201.6
B8: 3 | C8: =COUNTIF('Raw Data'!$L$2:$L$7992,$B8) -> 172 | D8: =SUMIF('Raw Data'!$L$2:$L$7992,$B8,'Raw Data'!$M$2:$M$7992) -> 764 | E8: =SUMIF('Raw Data'!$L$2:$L$7992,$B8,'Raw Data'!$Q$2:$Q$7992) -> 1612535.4 | F8: =SUMIF('Raw Data'!$L$2:$L$7992,$B8,'Raw Data'!$R$2:$R$7992) -> 1121715.3 | G8: =E8-F8 -> 490820.09 | H8: =IFERROR(G8/E8,0) -> 0.30437787 | J8: 2 | K8: =INDEX($B$6:$B$52,MATCH(LARGE($E$6:$E$52,J8),$E$6:$E$52,0)) -> 40 | L8: =LARGE($E$6:$E$52,J8) -> 1868085.1
B9: 4 | C9: =COUNTIF('Raw Data'!$L$2:$L$7992,$B9) -> 200 | D9: =SUMIF('Raw Data'!$L$2:$L$7992,$B9,'Raw Data'!$M$2:$M$7992) -> 878 | E9: =SUMIF('Raw Data'!$L$2:$L$7992,$B9,'Raw Data'!$Q$2:$Q$7992) -> 1787987.8 | F9: =SUMIF('Raw Data'!$L$2:$L$7992,$B9,'Raw Data'!$R$2:$R$7992) -> 1285268.9 | G9: =E9-F9 -> 502718.89 | H9: =IFERROR(G9/E9,0) -> 0.28116461 | J9: 3 | K9: =INDEX($B$6:$B$52,MATCH(LARGE($E$6:$E$52,J9),$E$6:$E$52,0)) -> 37 | L9: =LARGE($E$6:$E$52,J9) -> 1830094.1
B10: 5 | C10: =COUNTIF('Raw Data'!$L$2:$L$7992,$B10) -> 173 | D10: =SUMIF('Raw Data'!$L$2:$L$7992,$B10,'Raw Data'!$M$2:$M$7992) -> 811 | E10: =SUMIF('Raw Data'!$L$2:$L$7992,$B10,'Raw Data'!$Q$2:$Q$7992) -> 1804941.8 | F10: =SUMIF('Raw Data'!$L$2:$L$7992,$B10,'Raw Data'!$R$2:$R$7992) -> 1260351.9 | G10: =E10-F10 -> 544589.95 | H10: =IFERROR(G10/E10,0) -> 0.30172161 | J10: 4 | K10: =INDEX($B$6:$B$52,MATCH(LARGE($E$6:$E$52,J10),$E$6:$E$52,0)) -> 41 | L10: =LARGE($E$6:$E$52,J10) -> 1809669.3
B11: 6 | C11: =COUNTIF('Raw Data'!$L$2:$L$7992,$B11) -> 154 | D11: =SUMIF('Raw Data'!$L$2:$L$7992,$B11,'Raw Data'!$M$2:$M$7992) -> 663 | E11: =SUMIF('Raw Data'!$L$2:$L$7992,$B11,'Raw Data'!$Q$2:$Q$7992) -> 1272748.2 | F11: =SUMIF('Raw Data'!$L$2:$L$7992,$B11,'Raw Data'!$R$2:$R$7992) -> 892191.36 | G11: =E11-F11 -> 380556.89 | H11: =IFERROR(G11/E11,0) -> 0.29900406 | J11: 5 | K11: =INDEX($B$6:$B$52,MATCH(LARGE($E$6:$E$52,J11),$E$6:$E$52,0)) -> 5 | L11: =LARGE($E$6:$E$52,J11) -> 1804941.8
B12: 7 | C12: =COUNTIF('Raw Data'!$L$2:$L$7992,$B12) -> 166 | D12: =SUMIF('Raw Data'!$L$2:$L$7992,$B12,'Raw Data'!$M$2:$M$7992) -> 735 | E12: =SUMIF('Raw Data'!$L$2:$L$7992,$B12,'Raw Data'!$Q$2:$Q$7992) -> 1536014.4 | F12: =SUMIF('Raw Data'!$L$2:$L$7992,$B12,'Raw Data'!$R$2:$R$7992) -> 1058522.9 | G12: =E12-F12 -> 477491.47 | H12: =IFERROR(G12/E12,0) -> 0.31086394 | J12: 6 | K12: =INDEX($B$6:$B$52,MATCH(LARGE($E$6:$E$52,J12),$E$6:$E$52,0)) -> 4 | L12: =LARGE($E$6:$E$52,J12) -> 1787987.8
B13: 8 | C13: =COUNTIF('Raw Data'!$L$2:$L$7992,$B13) -> 195 | D13: =SUMIF('Raw Data'!$L$2:$L$7992,$B13,'Raw Data'!$M$2:$M$7992) -> 879 | E13: =SUMIF('Raw Data'!$L$2:$L$7992,$B13,'Raw Data'!$Q$2:$Q$7992) -> 1720609.2 | F13: =SUMIF('Raw Data'!$L$2:$L$7992,$B13,'Raw Data'!$R$2:$R$7992) -> 1180857.8 | G13: =E13-F13 -> 539751.47 | H13: =IFERROR(G13/E13,0) -> 0.31369788 | J13: 7 | K13: =INDEX($B$6:$B$52,MATCH(LARGE($E$6:$E$52,J13),$E$6:$E$52,0)) -> 2 | L13: =LARGE($E$6:$E$52,J13) -> 1775222.3
B14: 9 | C14: =COUNTIF('Raw Data'!$L$2:$L$7992,$B14) -> 170 | D14: =SUMIF('Raw Data'!$L$2:$L$7992,$B14,'Raw Data'!$M$2:$M$7992) -> 772 | E14: =SUMIF('Raw Data'!$L$2:$L$7992,$B14,'Raw Data'!$Q$2:$Q$7992) -> 1447155.1 | F14: =SUMIF('Raw Data'!$L$2:$L$7992,$B14,'Raw Data'!$R$2:$R$7992) -> 1028895.2 | G14: =E14-F14 -> 418259.96 | H14: =IFERROR(G14/E14,0) -> 0.2890222 | J14: 8 | K14: =INDEX($B$6:$B$52,MATCH(LARGE($E$6:$E$52,J14),$E$6:$E$52,0)) -> 35 | L14: =LARGE($E$6:$E$52,J14) -> 1765169.9
B15: 10 | C15: =COUNTIF('Raw Data'!$L$2:$L$7992,$B15) -> 168 | D15: =SUMIF('Raw Data'!$L$2:$L$7992,$B15,'Raw Data'!$M$2:$M$7992) -> 755 | E15: =SUMIF('Raw Data'!$L$2:$L$7992,$B15,'Raw Data'!$Q$2:$Q$7992) -> 1650902.3 | F15: =SUMIF('Raw Data'!$L$2:$L$7992,$B15,'Raw Data'!$R$2:$R$7992) -> 1158168.5 | G15: =E15-F15 -> 492733.81 | H15: =IFERROR(G15/E15,0) -> 0.29846334 | J15: 9 | K15: =INDEX($B$6:$B$52,MATCH(LARGE($E$6:$E$52,J15),$E$6:$E$52,0)) -> 8 | L15: =LARGE($E$6:$E$52,J15) -> 1720609.2
B16: 11 | C16: =COUNTIF('Raw Data'!$L$2:$L$7992,$B16) -> 182 | D16: =SUMIF('Raw Data'!$L$2:$L$7992,$B16,'Raw Data'!$M$2:$M$7992) -> 814 | E16: =SUMIF('Raw Data'!$L$2:$L$7992,$B16,'Raw Data'!$Q$2:$Q$7992) -> 1648318.3 | F16: =SUMIF('Raw Data'!$L$2:$L$7992,$B16,'Raw Data'!$R$2:$R$7992) -> 1144228.3 | G16: =E16-F16 -> 504089.91 | H16: =IFERROR(G16/E16,0) -> 0.30582074 | J16: 10 | K16: =INDEX($B$6:$B$52,MATCH(LARGE($E$6:$E$52,J16),$E$6:$E$52,0)) -> 17 | L16: =LARGE($E$6:$E$52,J16) -> 1714489.5
B17: 12 | C17: =COUNTIF('Raw Data'!$L$2:$L$7992,$B17) -> 181 | D17: =SUMIF('Raw Data'!$L$2:$L$7992,$B17,'Raw Data'!$M$2:$M$7992) -> 827 | E17: =SUMIF('Raw Data'!$L$2:$L$7992,$B17,'Raw Data'!$Q$2:$Q$7992) -> 1624594.2 | F17: =SUMIF('Raw Data'!$L$2:$L$7992,$B17,'Raw Data'!$R$2:$R$7992) -> 1174168.8 | G17: =E17-F17 -> 450425.4 | H17: =IFERROR(G17/E17,0) -> 0.27725409
B18: 13 | C18: =COUNTIF('Raw Data'!$L$2:$L$7992,$B18) -> 175 | D18: =SUMIF('Raw Data'!$L$2:$L$7992,$B18,'Raw Data'!$M$2:$M$7992) -> 777 | E18: =SUMIF('Raw Data'!$L$2:$L$7992,$B18,'Raw Data'!$Q$2:$Q$7992) -> 1458502.7 | F18: =SUMIF('Raw Data'!$L$2:$L$7992,$B18,'Raw Data'!$R$2:$R$7992) -> 1074851.9 | G18: =E18-F18 -> 383650.87 | H18: =IFERROR(G18/E18,0) -> 0.26304433
B19: 14 | C19: =COUNTIF('Raw Data'!$L$2:$L$7992,$B19) -> 163 | D19: =SUMIF('Raw Data'!$L$2:$L$7992,$B19,'Raw Data'!$M$2:$M$7992) -> 766 | E19: =SUMIF('Raw Data'!$L$2:$L$7992,$B19,'Raw Data'!$Q$2:$Q$7992) -> 1675033.8 | F19: =SUMIF('Raw Data'!$L$2:$L$7992,$B19,'Raw Data'!$R$2:$R$7992) -> 1182806.3 | G19: =E19-F19 -> 492227.51 | H19: =IFERROR(G19/E19,0) -> 0.29386123 | J19: Top 10 Products by Units Sold
B20: 15 | C20: =COUNTIF('Raw Data'!$L$2:$L$7992,$B20) -> 157 | D20: =SUMIF('Raw Data'!$L$2:$L$7992,$B20,'Raw Data'!$M$2:$M$7992) -> 658 | E20: =SUMIF('Raw Data'!$L$2:$L$7992,$B20,'Raw Data'!$Q$2:$Q$7992) -> 1422543.5 | F20: =SUMIF('Raw Data'!$L$2:$L$7992,$B20,'Raw Data'!$R$2:$R$7992) -> 1062253.7 | G20: =E20-F20 -> 360289.78 | H20: =IFERROR(G20/E20,0) -> 0.25327154 | J20: Rank | K20: Product ID | L20: Units Sold
B21: 16 | C21: =COUNTIF('Raw Data'!$L$2:$L$7992,$B21) -> 177 | D21: =SUMIF('Raw Data'!$L$2:$L$7992,$B21,'Raw Data'!$M$2:$M$7992) -> 814 | E21: =SUMIF('Raw Data'!$L$2:$L$7992,$B21,'Raw Data'!$Q$2:$Q$7992) -> 1674013.4 | F21: =SUMIF('Raw Data'!$L$2:$L$7992,$B21,'Raw Data'!$R$2:$R$7992) -> 1150306.3 | G21: =E21-F21 -> 523707.16 | H21: =IFERROR(G21/E21,0) -> 0.31284526 | J21: 1 | K21: =INDEX($B$6:$B$52,MATCH(LARGE($D$6:$D$52,J21),$D$6:$D$52,0)) -> 23 | L21: =LARGE($D$6:$D$52,J21) -> 956
B22: 17 | C22: =COUNTIF('Raw Data'!$L$2:$L$7992,$B22) -> 178 | D22: =SUMIF('Raw Data'!$L$2:$L$7992,$B22,'Raw Data'!$M$2:$M$7992) -> 807 | E22: =SUMIF('Raw Data'!$L$2:$L$7992,$B22,'Raw Data'!$Q$2:$Q$7992) -> 1714489.5 | F22: =SUMIF('Raw Data'!$L$2:$L$7992,$B22,'Raw Data'!$R$2:$R$7992) -> 1208496.4 | G22: =E22-F22 -> 505993.08 | H22: =IFERROR(G22/E22,0) -> 0.29512755 | J22: 2 | K22: =INDEX($B$6:$B$52,MATCH(LARGE($D$6:$D$52,J22),$D$6:$D$52,0)) -> 37 | L22: =LARGE($D$6:$D$52,J22) -> 896
B23: 18 | C23: =COUNTIF('Raw Data'!$L$2:$L$7992,$B23) -> 156 | D23: =SUMIF('Raw Data'!$L$2:$L$7992,$B23,'Raw Data'!$M$2:$M$7992) -> 644 | E23: =SUMIF('Raw Data'!$L$2:$L$7992,$B23,'Raw Data'!$Q$2:$Q$7992) -> 1465287.3 | F23: =SUMIF('Raw Data'!$L$2:$L$7992,$B23,'Raw Data'!$R$2:$R$7992) -> 1069166.9 | G23: =E23-F23 -> 396120.44 | H23: =IFERROR(G23/E23,0) -> 0.27033636 | J23: 3 | K23: =INDEX($B$6:$B$52,MATCH(LARGE($D$6:$D$52,J23),$D$6:$D$52,0)) -> 8 | L23: =LARGE($D$6:$D$52,J23) -> 879
B24: 19 | C24: =COUNTIF('Raw Data'!$L$2:$L$7992,$B24) -> 164 | D24: =SUMIF('Raw Data'!$L$2:$L$7992,$B24,'Raw Data'!$M$2:$M$7992) -> 772 | E24: =SUMIF('Raw Data'!$L$2:$L$7992,$B24,'Raw Data'!$Q$2:$Q$7992) -> 1586896.5 | F24: =SUMIF('Raw Data'!$L$2:$L$7992,$B24,'Raw Data'!$R$2:$R$7992) -> 1113953.7 | G24: =E24-F24 -> 472942.77 | H24: =IFERROR(G24/E24,0) -> 0.29803 | J24: 4 | K24: =INDEX($B$6:$B$52,MATCH(LARGE($D$6:$D$52,J24),$D$6:$D$52,0)) -> 4 | L24: =LARGE($D$6:$D$52,J24) -> 878
B25: 20 | C25: =COUNTIF('Raw Data'!$L$2:$L$7992,$B25) -> 170 | D25: =SUMIF('Raw Data'!$L$2:$L$7992,$B25,'Raw Data'!$M$2:$M$7992) -> 798 | E25: =SUMIF('Raw Data'!$L$2:$L$7992,$B25,'Raw Data'!$Q$2:$Q$7992) -> 1594396.5 | F25: =SUMIF('Raw Data'!$L$2:$L$7992,$B25,'Raw Data'!$R$2:$R$7992) -> 1138904 | G25: =E25-F25 -> 455492.5 | H25: =IFERROR(G25/E25,0) -> 0.28568333 | J25: 5 | K25: =INDEX($B$6:$B$52,MATCH(LARGE($D$6:$D$52,J25),$D$6:$D$52,0)) -> 40 | L25: =LARGE($D$6:$D$52,J25) -> 855
B26: 21 | C26: =COUNTIF('Raw Data'!$L$2:$L$7992,$B26) -> 168 | D26: =SUMIF('Raw Data'!$L$2:$L$7992,$B26,'Raw Data'!$M$2:$M$7992) -> 789 | E26: =SUMIF('Raw Data'!$L$2:$L$7992,$B26,'Raw Data'!$Q$2:$Q$7992) -> 1633697.3 | F26: =SUMIF('Raw Data'!$L$2:$L$7992,$B26,'Raw Data'!$R$2:$R$7992) -> 1137303.3 | G26: =E26-F26 -> 496394.01 | H26: =IFERROR(G26/E26,0) -> 0.30384698 | J26: 6 | K26: =INDEX($B$6:$B$52,MATCH(LARGE($D$6:$D$52,J26),$D$6:$D$52,0)) -> 41 | L26: =LARGE($D$6:$D$52,J26) -> 854
B27: 22 | C27: =COUNTIF('Raw Data'!$L$2:$L$7992,$B27) -> 168 | D27: =SUMIF('Raw Data'!$L$2:$L$7992,$B27,'Raw Data'!$M$2:$M$7992) -> 837 | E27: =SUMIF('Raw Data'!$L$2:$L$7992,$B27,'Raw Data'!$Q$2:$Q$7992) -> 1544518.7 | F27: =SUMIF('Raw Data'!$L$2:$L$7992,$B27,'Raw Data'!$R$2:$R$7992) -> 1077699.7 | G27: =E27-F27 -> 466818.98 | H27: =IFERROR(G27/E27,0) -> 0.30224237 | J27: 7 | K27: =INDEX($B$6:$B$52,MATCH(LARGE($D$6:$D$52,J27),$D$6:$D$52,0)) -> 22 | L27: =LARGE($D$6:$D$52,J27) -> 837
B28: 23 | C28: =COUNTIF('Raw Data'!$L$2:$L$7992,$B28) -> 194 | D28: =SUMIF('Raw Data'!$L$2:$L$7992,$B28,'Raw Data'!$M$2:$M$7992) -> 956 | E28: =SUMIF('Raw Data'!$L$2:$L$7992,$B28,'Raw Data'!$Q$2:$Q$7992) -> 2101201.6 | F28: =SUMIF('Raw Data'!$L$2:$L$7992,$B28,'Raw Data'!$R$2:$R$7992) -> 1449969.8 | G28: =E28-F28 -> 651231.74 | H28: =IFERROR(G28/E28,0) -> 0.30993302 | J28: 8 | K28: =INDEX($B$6:$B$52,MATCH(LARGE($D$6:$D$52,J28),$D$6:$D$52,0)) -> 38 | L28: =LARGE($D$6:$D$52,J28) -> 832
B29: 24 | C29: =COUNTIF('Raw Data'!$L$2:$L$7992,$B29) -> 163 | D29: =SUMIF('Raw Data'!$L$2:$L$7992,$B29,'Raw Data'!$M$2:$M$7992) -> 759 | E29: =SUMIF('Raw Data'!$L$2:$L$7992,$B29,'Raw Data'!$Q$2:$Q$7992) -> 1590446.7 | F29: =SUMIF('Raw Data'!$L$2:$L$7992,$B29,'Raw Data'!$R$2:$R$7992) -> 1126402.8 | G29: =E29-F29 -> 464043.92 | H29: =IFERROR(G29/E29,0) -> 0.29176956 | J29: 9 | K29: =INDEX($B$6:$B$52,MATCH(LARGE($D$6:$D$52,J29),$D$6:$D$52,0)) -> 27 | L29: =LARGE($D$6:$D$52,J29) -> 830
B30: 25 | C30: =COUNTIF('Raw Data'!$L$2:$L$7992,$B30) -> 180 | D30: =SUMIF('Raw Data'!$L$2:$L$7992,$B30,'Raw Data'!$M$2:$M$7992) -> 809 | E30: =SUMIF('Raw Data'!$L$2:$L$7992,$B30,'Raw Data'!$Q$2:$Q$7992) -> 1608852.9 | F30: =SUMIF('Raw Data'!$L$2:$L$7992,$B30,'Raw Data'!$R$2:$R$7992) -> 1115805.3 | G30: =E30-F30 -> 493047.59 | H30: =IFERROR(G30/E30,0) -> 0.30645908 | J30: 10 | K30: =INDEX($B$6:$B$52,MATCH(LARGE($D$6:$D$52,J30),$D$6:$D$52,0)) -> 12 | L30: =LARGE($D$6:$D$52,J30) -> 827
B31: 26 | C31: =COUNTIF('Raw Data'!$L$2:$L$7992,$B31) -> 158 | D31: =SUMIF('Raw Data'!$L$2:$L$7992,$B31,'Raw Data'!$M$2:$M$7992) -> 723 | E31: =SUMIF('Raw Data'!$L$2:$L$7992,$B31,'Raw Data'!$Q$2:$Q$7992) -> 1408047.4 | F31: =SUMIF('Raw Data'!$L$2:$L$7992,$B31,'Raw Data'!$R$2:$R$7992) -> 980463.15 | G31: =E31-F31 -> 427584.23 | H31: =IFERROR(G31/E31,0) -> 0.30367176
B32: 27 | C32: =COUNTIF('Raw Data'!$L$2:$L$7992,$B32) -> 190 | D32: =SUMIF('Raw Data'!$L$2:$L$7992,$B32,'Raw Data'!$M$2:$M$7992) -> 830 | E32: =SUMIF('Raw Data'!$L$2:$L$7992,$B32,'Raw Data'!$Q$2:$Q$7992) -> 1583174.8 | F32: =SUMIF('Raw Data'!$L$2:$L$7992,$B32,'Raw Data'!$R$2:$R$7992) -> 1126679.2 | G32: =E32-F32 -> 456495.6 | H32: =IFERROR(G32/E32,0) -> 0.28834188
B33: 28 | C33: =COUNTIF('Raw Data'!$L$2:$L$7992,$B33) -> 178 | D33: =SUMIF('Raw Data'!$L$2:$L$7992,$B33,'Raw Data'!$M$2:$M$7992) -> 809 | E33: =SUMIF('Raw Data'!$L$2:$L$7992,$B33,'Raw Data'!$Q$2:$Q$7992) -> 1487598.7 | F33: =SUMIF('Raw Data'!$L$2:$L$7992,$B33,'Raw Data'!$R$2:$R$7992) -> 1068638.7 | G33: =E33-F33 -> 418959.99 | H33: =IFERROR(G33/E33,0) -> 0.2816351 | J33: Top 10 Products by Margin %
B34: 29 | C34: =COUNTIF('Raw Data'!$L$2:$L$7992,$B34) -> 176 | D34: =SUMIF('Raw Data'!$L$2:$L$7992,$B34,'Raw Data'!$M$2:$M$7992) -> 818 | E34: =SUMIF('Raw Data'!$L$2:$L$7992,$B34,'Raw Data'!$Q$2:$Q$7992) -> 1686453.1 | F34: =SUMIF('Raw Data'!$L$2:$L$7992,$B34,'Raw Data'!$R$2:$R$7992) -> 1233545.4 | G34: =E34-F34 -> 452907.77 | H34: =IFERROR(G34/E34,0) -> 0.26855639 | J34: Rank | K34: Product ID | L34: Margin %
B35: 30 | C35: =COUNTIF('Raw Data'!$L$2:$L$7992,$B35) -> 156 | D35: =SUMIF('Raw Data'!$L$2:$L$7992,$B35,'Raw Data'!$M$2:$M$7992) -> 656 | E35: =SUMIF('Raw Data'!$L$2:$L$7992,$B35,'Raw Data'!$Q$2:$Q$7992) -> 1357710.3 | F35: =SUMIF('Raw Data'!$L$2:$L$7992,$B35,'Raw Data'!$R$2:$R$7992) -> 972605.09 | G35: =E35-F35 -> 385105.19 | H35: =IFERROR(G35/E35,0) -> 0.28364313 | J35: 1 | K35: =INDEX($B$6:$B$52,MATCH(LARGE($H$6:$H$52,J35),$H$6:$H$52,0)) -> 8 | L35: =LARGE($H$6:$H$52,J35) -> 0.31369788
B36: 31 | C36: =COUNTIF('Raw Data'!$L$2:$L$7992,$B36) -> 169 | D36: =SUMIF('Raw Data'!$L$2:$L$7992,$B36,'Raw Data'!$M$2:$M$7992) -> 768 | E36: =SUMIF('Raw Data'!$L$2:$L$7992,$B36,'Raw Data'!$Q$2:$Q$7992) -> 1378742.8 | F36: =SUMIF('Raw Data'!$L$2:$L$7992,$B36,'Raw Data'!$R$2:$R$7992) -> 1022618.1 | G36: =E36-F36 -> 356124.61 | H36: =IFERROR(G36/E36,0) -> 0.25829663 | J36: 2 | K36: =INDEX($B$6:$B$52,MATCH(LARGE($H$6:$H$52,J36),$H$6:$H$52,0)) -> 16 | L36: =LARGE($H$6:$H$52,J36) -> 0.31284526
B37: 32 | C37: =COUNTIF('Raw Data'!$L$2:$L$7992,$B37) -> 145 | D37: =SUMIF('Raw Data'!$L$2:$L$7992,$B37,'Raw Data'!$M$2:$M$7992) -> 660 | E37: =SUMIF('Raw Data'!$L$2:$L$7992,$B37,'Raw Data'!$Q$2:$Q$7992) -> 1255641.8 | F37: =SUMIF('Raw Data'!$L$2:$L$7992,$B37,'Raw Data'!$R$2:$R$7992) -> 870214.23 | G37: =E37-F37 -> 385427.58 | H37: =IFERROR(G37/E37,0) -> 0.30695663 | J37: 3 | K37: =INDEX($B$6:$B$52,MATCH(LARGE($H$6:$H$52,J37),$H$6:$H$52,0)) -> 2 | L37: =LARGE($H$6:$H$52,J37) -> 0.31161378
B38: 33 | C38: =COUNTIF('Raw Data'!$L$2:$L$7992,$B38) -> 166 | D38: =SUMIF('Raw Data'!$L$2:$L$7992,$B38,'Raw Data'!$M$2:$M$7992) -> 695 | E38: =SUMIF('Raw Data'!$L$2:$L$7992,$B38,'Raw Data'!$Q$2:$Q$7992) -> 1363547.7 | F38: =SUMIF('Raw Data'!$L$2:$L$7992,$B38,'Raw Data'!$R$2:$R$7992) -> 960474.98 | G38: =E38-F38 -> 403072.67 | H38: =IFERROR(G38/E38,0) -> 0.29560586 | J38: 4 | K38: =INDEX($B$6:$B$52,MATCH(LARGE($H$6:$H$52,J38),$H$6:$H$52,0)) -> 7 | L38: =LARGE($H$6:$H$52,J38) -> 0.31086394
B39: 34 | C39: =COUNTIF('Raw Data'!$L$2:$L$7992,$B39) -> 152 | D39: =SUMIF('Raw Data'!$L$2:$L$7992,$B39,'Raw Data'!$M$2:$M$7992) -> 635 | E39: =SUMIF('Raw Data'!$L$2:$L$7992,$B39,'Raw Data'!$Q$2:$Q$7992) -> 1237191.7 | F39: =SUMIF('Raw Data'!$L$2:$L$7992,$B39,'Raw Data'!$R$2:$R$7992) -> 871113.96 | G39: =E39-F39 -> 366077.72 | H39: =IFERROR(G39/E39,0) -> 0.2958941 | J39: 5 | K39: =INDEX($B$6:$B$52,MATCH(LARGE($H$6:$H$52,J39),$H$6:$H$52,0)) -> 23 | L39: =LARGE($H$6:$H$52,J39) -> 0.30993302
B40: 35 | C40: =COUNTIF('Raw Data'!$L$2:$L$7992,$B40) -> 168 | D40: =SUMIF('Raw Data'!$L$2:$L$7992,$B40,'Raw Data'!$M$2:$M$7992) -> 770 | E40: =SUMIF('Raw Data'!$L$2:$L$7992,$B40,'Raw Data'!$Q$2:$Q$7992) -> 1765169.9 | F40: =SUMIF('Raw Data'!$L$2:$L$7992,$B40,'Raw Data'!$R$2:$R$7992) -> 1240526 | G40: =E40-F40 -> 524643.92 | H40: =IFERROR(G40/E40,0) -> 0.29722006 | J40: 6 | K40: =INDEX($B$6:$B$52,MATCH(LARGE($H$6:$H$52,J40),$H$6:$H$52,0)) -> 39 | L40: =LARGE($H$6:$H$52,J40) -> 0.30710707
B41: 36 | C41: =COUNTIF('Raw Data'!$L$2:$L$7992,$B41) -> 170 | D41: =SUMIF('Raw Data'!$L$2:$L$7992,$B41,'Raw Data'!$M$2:$M$7992) -> 769 | E41: =SUMIF('Raw Data'!$L$2:$L$7992,$B41,'Raw Data'!$Q$2:$Q$7992) -> 1508051.4 | F41: =SUMIF('Raw Data'!$L$2:$L$7992,$B41,'Raw Data'!$R$2:$R$7992) -> 1093253.8 | G41: =E41-F41 -> 414797.66 | H41: =IFERROR(G41/E41,0) -> 0.27505538 | J41: 7 | K41: =INDEX($B$6:$B$52,MATCH(LARGE($H$6:$H$52,J41),$H$6:$H$52,0)) -> 32 | L41: =LARGE($H$6:$H$52,J41) -> 0.30695663
B42: 37 | C42: =COUNTIF('Raw Data'!$L$2:$L$7992,$B42) -> 200 | D42: =SUMIF('Raw Data'!$L$2:$L$7992,$B42,'Raw Data'!$M$2:$M$7992) -> 896 | E42: =SUMIF('Raw Data'!$L$2:$L$7992,$B42,'Raw Data'!$Q$2:$Q$7992) -> 1830094.1 | F42: =SUMIF('Raw Data'!$L$2:$L$7992,$B42,'Raw Data'!$R$2:$R$7992) -> 1309697 | G42: =E42-F42 -> 520397.14 | H42: =IFERROR(G42/E42,0) -> 0.2843554 | J42: 8 | K42: =INDEX($B$6:$B$52,MATCH(LARGE($H$6:$H$52,J42),$H$6:$H$52,0)) -> 25 | L42: =LARGE($H$6:$H$52,J42) -> 0.30645908
...

Sheet Warehouse Analysis
B2: Warehouse Volume & Performance
B3: Which warehouses handle the most volume?
B5: Warehouse | C5: Orders | D5: Units Sold | E5: Revenue | F5: Profit | G5: Margin % | H5: Avg Order→Ship (days)
B6: WARE-MKL1006 | C6: =COUNTIF('Raw Data'!$C$2:$C$7992,$B6) -> 857 | D6: =SUMIF('Raw Data'!$C$2:$C$7992,$B6,'Raw Data'!$M$2:$M$7992) -> 3816 | E6: =SUMIF('Raw Data'!$C$2:$C$7992,$B6,'Raw Data'!$Q$2:$Q$7992) -> 7813119.7 | F6: =SUMIF('Raw Data'!$C$2:$C$7992,$B6,'Raw Data'!$S$2:$S$7992) -> 2347053.9 | G6: =IFERROR(F6/E6,0) -> 0.30039907 | H6: =AVERAGEIF('Raw Data'!$C$2:$C$7992,$B6,'Raw Data'!$U$2:$U$7992) -> 14.955659
B7: WARE-NBV1002 | C7: =COUNTIF('Raw Data'!$C$2:$C$7992,$B7) -> 691 | D7: =SUMIF('Raw Data'!$C$2:$C$7992,$B7,'Raw Data'!$M$2:$M$7992) -> 3101 | E7: =SUMIF('Raw Data'!$C$2:$C$7992,$B7,'Raw Data'!$Q$2:$Q$7992) -> 6096532.2 | F7: =SUMIF('Raw Data'!$C$2:$C$7992,$B7,'Raw Data'!$S$2:$S$7992) -> 1788358.8 | G7: =IFERROR(F7/E7,0) -> 0.29334033 | H7: =AVERAGEIF('Raw Data'!$C$2:$C$7992,$B7,'Raw Data'!$U$2:$U$7992) -> 15.269175
B8: WARE-NMK1003 | C8: =COUNTIF('Raw Data'!$C$2:$C$7992,$B8) -> 2505 | D8: =SUMIF('Raw Data'!$C$2:$C$7992,$B8,'Raw Data'!$M$2:$M$7992) -> 11351 | E8: =SUMIF('Raw Data'!$C$2:$C$7992,$B8,'Raw Data'!$Q$2:$Q$7992) -> 23136974 | F8: =SUMIF('Raw Data'!$C$2:$C$7992,$B8,'Raw Data'!$S$2:$S$7992) -> 6782678.6 | G8: =IFERROR(F8/E8,0) -> 0.29315323 | H8: =AVERAGEIF('Raw Data'!$C$2:$C$7992,$B8,'Raw Data'!$U$2:$U$7992) -> 15.453892
B9: WARE-PUJ1005 | C9: =COUNTIF('Raw Data'!$C$2:$C$7992,$B9) -> 1451 | D9: =SUMIF('Raw Data'!$C$2:$C$7992,$B9,'Raw Data'!$M$2:$M$7992) -> 6572 | E9: =SUMIF('Raw Data'!$C$2:$C$7992,$B9,'Raw Data'!$Q$2:$Q$7992) -> 13056173 | F9: =SUMIF('Raw Data'!$C$2:$C$7992,$B9,'Raw Data'!$S$2:$S$7992) -> 3836435.9 | G9: =IFERROR(F9/E9,0) -> 0.29384076 | H9: =AVERAGEIF('Raw Data'!$C$2:$C$7992,$B9,'Raw Data'!$U$2:$U$7992) -> 14.971054
B10: WARE-UHY1004 | C10: =COUNTIF('Raw Data'!$C$2:$C$7992,$B10) -> 1265 | D10: =SUMIF('Raw Data'!$C$2:$C$7992,$B10,'Raw Data'!$M$2:$M$7992) -> 5765 | E10: =SUMIF('Raw Data'!$C$2:$C$7992,$B10,'Raw Data'!$Q$2:$Q$7992) -> 11985686 | F10: =SUMIF('Raw Data'!$C$2:$C$7992,$B10,'Raw Data'!$S$2:$S$7992) -> 3436949.9 | G10: =IFERROR(F10/E10,0) -> 0.28675454 | H10: =AVERAGEIF('Raw Data'!$C$2:$C$7992,$B10,'Raw Data'!$U$2:$U$7992) -> 15.267194
B11: WARE-XYS1001 | C11: =COUNTIF('Raw Data'!$C$2:$C$7992,$B11) -> 1222 | D11: =SUMIF('Raw Data'!$C$2:$C$7992,$B11,'Raw Data'!$M$2:$M$7992) -> 5557 | E11: =SUMIF('Raw Data'!$C$2:$C$7992,$B11,'Raw Data'!$Q$2:$Q$7992) -> 11054894 | F11: =SUMIF('Raw Data'!$C$2:$C$7992,$B11,'Raw Data'!$S$2:$S$7992) -> 3133833.6 | G11: =IFERROR(F11/E11,0) -> 0.2834793 | H11: =AVERAGEIF('Raw Data'!$C$2:$C$7992,$B11,'Raw Data'!$U$2:$U$7992) -> 14.810966

Sheet Regional Analysis
B2: Regional Performance (Proxied by Warehouse Location)
B3: Which regions outperform? — Note: the source data has no explicit Region/State field.
B4: The 6 warehouse locations are used here as the best available proxy for geographic performance.
B6: Warehouse (Region Proxy) | C6: Revenue | D6: Profit | E6: Margin % | F6: Units Sold | G6: Orders | H6: Revenue per Order | I6: % of Total Revenue
B7: WARE-MKL1006 | C7: =SUMIF('Raw Data'!$C$2:$C$7992,$B7,'Raw Data'!$Q$2:$Q$7992) -> 7813119.7 | D7: =SUMIF('Raw Data'!$C$2:$C$7992,$B7,'Raw Data'!$S$2:$S$7992) -> 2347053.9 | E7: =IFERROR(D7/C7,0) -> 0.30039907 | F7: =SUMIF('Raw Data'!$C$2:$C$7992,$B7,'Raw Data'!$M$2:$M$7992) -> 3816 | G7: =COUNTIF('Raw Data'!$C$2:$C$7992,$B7) -> 857 | H7: =IFERROR(C7/G7,0) -> 9116.8258 | I7: =C7/SUM($C$7:$C$12) -> 0.10681923
B8: WARE-NBV1002 | C8: =SUMIF('Raw Data'!$C$2:$C$7992,$B8,'Raw Data'!$Q$2:$Q$7992) -> 6096532.2 | D8: =SUMIF('Raw Data'!$C$2:$C$7992,$B8,'Raw Data'!$S$2:$S$7992) -> 1788358.8 | E8: =IFERROR(D8/C8,0) -> 0.29334033 | F8: =SUMIF('Raw Data'!$C$2:$C$7992,$B8,'Raw Data'!$M$2:$M$7992) -> 3101 | G8: =COUNTIF('Raw Data'!$C$2:$C$7992,$B8) -> 691 | H8: =IFERROR(C8/G8,0) -> 8822.7673 | I8: =C8/SUM($C$7:$C$12) -> 0.08335043
B9: WARE-NMK1003 | C9: =SUMIF('Raw Data'!$C$2:$C$7992,$B9,'Raw Data'!$Q$2:$Q$7992) -> 23136974 | D9: =SUMIF('Raw Data'!$C$2:$C$7992,$B9,'Raw Data'!$S$2:$S$7992) -> 6782678.6 | E9: =IFERROR(D9/C9,0) -> 0.29315323 | F9: =SUMIF('Raw Data'!$C$2:$C$7992,$B9,'Raw Data'!$M$2:$M$7992) -> 11351 | G9: =COUNTIF('Raw Data'!$C$2:$C$7992,$B9) -> 2505 | H9: =IFERROR(C9/G9,0) -> 9236.317 | I9: =C9/SUM($C$7:$C$12) -> 0.31632356
B10: WARE-PUJ1005 | C10: =SUMIF('Raw Data'!$C$2:$C$7992,$B10,'Raw Data'!$Q$2:$Q$7992) -> 13056173 | D10: =SUMIF('Raw Data'!$C$2:$C$7992,$B10,'Raw Data'!$S$2:$S$7992) -> 3836435.9 | E10: =IFERROR(D10/C10,0) -> 0.29384076 | F10: =SUMIF('Raw Data'!$C$2:$C$7992,$B10,'Raw Data'!$M$2:$M$7992) -> 6572 | G10: =COUNTIF('Raw Data'!$C$2:$C$7992,$B10) -> 1451 | H10: =IFERROR(C10/G10,0) -> 8998.052 | I10: =C10/SUM($C$7:$C$12) -> 0.1785011
B11: WARE-UHY1004 | C11: =SUMIF('Raw Data'!$C$2:$C$7992,$B11,'Raw Data'!$Q$2:$Q$7992) -> 11985686 | D11: =SUMIF('Raw Data'!$C$2:$C$7992,$B11,'Raw Data'!$S$2:$S$7992) -> 3436949.9 | E11: =IFERROR(D11/C11,0) -> 0.28675454 | F11: =SUMIF('Raw Data'!$C$2:$C$7992,$B11,'Raw Data'!$M$2:$M$7992) -> 5765 | G11: =COUNTIF('Raw Data'!$C$2:$C$7992,$B11) -> 1265 | H11: =IFERROR(C11/G11,0) -> 9474.8507 | I11: =C11/SUM($C$7:$C$12) -> 0.16386563
B12: WARE-XYS1001 | C12: =SUMIF('Raw Data'!$C$2:$C$7992,$B12,'Raw Data'!$Q$2:$Q$7992) -> 11054894 | D12: =SUMIF('Raw Data'!$C$2:$C$7992,$B12,'Raw Data'!$S$2:$S$7992) -> 3133833.6 | E12: =IFERROR(D12/C12,0) -> 0.2834793 | F12: =SUMIF('Raw Data'!$C$2:$C$7992,$B12,'Raw Data'!$M$2:$M$7992) -> 5557 | G12: =COUNTIF('Raw Data'!$C$2:$C$7992,$B12) -> 1222 | H12: =IFERROR(C12/G12,0) -> 9046.5582 | I12: =C12/SUM($C$7:$C$12) -> 0.15114005

Sheet Fulfillment Analysis
B2: Order Fulfillment Speed
B3: How long does it take from order → ship → delivery, on average?
B5: Overall Averages (all orders)
B6: Order→Ship (days) | C6: Ship→Delivery (days) | D6: Order→Delivery (days)
B7: =AVERAGE('Raw Data'!U2:U7992) -> 15.16894 | C7: =AVERAGE('Raw Data'!V2:V7992) -> 5.5039419 | D7: =AVERAGE('Raw Data'!W2:W7992) -> 20.672882
B10: Average Fulfillment Time by Sales Channel
B11: Sales Channel | C11: Order→Ship | D11: Ship→Delivery | E11: Order→Delivery
B12: Distributor | C12: =AVERAGEIF('Raw Data'!$B$2:$B$7992,$B12,'Raw Data'!$U$2:$U$7992) -> 15.252364 | D12: =AVERAGEIF('Raw Data'!$B$2:$B$7992,$B12,'Raw Data'!$V$2:$V$7992) -> 5.6196364 | E12: =AVERAGEIF('Raw Data'!$B$2:$B$7992,$B12,'Raw Data'!$W$2:$W$7992) -> 20.872
B13: In-Store | C13: =AVERAGEIF('Raw Data'!$B$2:$B$7992,$B13,'Raw Data'!$U$2:$U$7992) -> 15.077926 | D13: =AVERAGEIF('Raw Data'!$B$2:$B$7992,$B13,'Raw Data'!$V$2:$V$7992) -> 5.4360218 | E13: =AVERAGEIF('Raw Data'!$B$2:$B$7992,$B13,'Raw Data'!$W$2:$W$7992) -> 20.513948
B14: Online | C14: =AVERAGEIF('Raw Data'!$B$2:$B$7992,$B14,'Raw Data'!$U$2:$U$7992) -> 15.32701 | D14: =AVERAGEIF('Raw Data'!$B$2:$B$7992,$B14,'Raw Data'!$V$2:$V$7992) -> 5.5468041 | E14: =AVERAGEIF('Raw Data'!$B$2:$B$7992,$B14,'Raw Data'!$W$2:$W$7992) -> 20.873814
B15: Wholesale | C15: =AVERAGEIF('Raw Data'!$B$2:$B$7992,$B15,'Raw Data'!$U$2:$U$7992) -> 14.947368 | D15: =AVERAGEIF('Raw Data'!$B$2:$B$7992,$B15,'Raw Data'!$V$2:$V$7992) -> 5.4602464 | E15: =AVERAGEIF('Raw Data'!$B$2:$B$7992,$B15,'Raw Data'!$W$2:$W$7992) -> 20.407615
B18: Average Fulfillment Time by Warehouse
B19: Warehouse | C19: Order→Ship | D19: Ship→Delivery | E19: Order→Delivery
B20: WARE-MKL1006 | C20: =AVERAGEIF('Raw Data'!$C$2:$C$7992,$B20,'Raw Data'!$U$2:$U$7992) -> 14.955659 | D20: =AVERAGEIF('Raw Data'!$C$2:$C$7992,$B20,'Raw Data'!$V$2:$V$7992) -> 5.3488915 | E20: =AVERAGEIF('Raw Data'!$C$2:$C$7992,$B20,'Raw Data'!$W$2:$W$7992) -> 20.304551
B21: WARE-NBV1002 | C21: =AVERAGEIF('Raw Data'!$C$2:$C$7992,$B21,'Raw Data'!$U$2:$U$7992) -> 15.269175 | D21: =AVERAGEIF('Raw Data'!$C$2:$C$7992,$B21,'Raw Data'!$V$2:$V$7992) -> 5.3777135 | E21: =AVERAGEIF('Raw Data'!$C$2:$C$7992,$B21,'Raw Data'!$W$2:$W$7992) -> 20.646889
B22: WARE-NMK1003 | C22: =AVERAGEIF('Raw Data'!$C$2:$C$7992,$B22,'Raw Data'!$U$2:$U$7992) -> 15.453892 | D22: =AVERAGEIF('Raw Data'!$C$2:$C$7992,$B22,'Raw Data'!$V$2:$V$7992) -> 5.5093812 | E22: =AVERAGEIF('Raw Data'!$C$2:$C$7992,$B22,'Raw Data'!$W$2:$W$7992) -> 20.963273
B23: WARE-PUJ1005 | C23: =AVERAGEIF('Raw Data'!$C$2:$C$7992,$B23,'Raw Data'!$U$2:$U$7992) -> 14.971054 | D23: =AVERAGEIF('Raw Data'!$C$2:$C$7992,$B23,'Raw Data'!$V$2:$V$7992) -> 5.5844245 | E23: =AVERAGEIF('Raw Data'!$C$2:$C$7992,$B23,'Raw Data'!$W$2:$W$7992) -> 20.555479
B24: WARE-UHY1004 | C24: =AVERAGEIF('Raw Data'!$C$2:$C$7992,$B24,'Raw Data'!$U$2:$U$7992) -> 15.267194 | D24: =AVERAGEIF('Raw Data'!$C$2:$C$7992,$B24,'Raw Data'!$V$2:$V$7992) -> 5.4964427 | E24: =AVERAGEIF('Raw Data'!$C$2:$C$7992,$B24,'Raw Data'!$W$2:$W$7992) -> 20.763636
B25: WARE-XYS1001 | C25: =AVERAGEIF('Raw Data'!$C$2:$C$7992,$B25,'Raw Data'!$U$2:$U$7992) -> 14.810966 | D25: =AVERAGEIF('Raw Data'!$C$2:$C$7992,$B25,'Raw Data'!$V$2:$V$7992) -> 5.5851064 | E25: =AVERAGEIF('Raw Data'!$C$2:$C$7992,$B25,'Raw Data'!$W$2:$W$7992) -> 20.396072

Sheet Monthly Trends
B2: Revenue & Profit Trend Over Time
B3: Monthly trend analysis, Jun 2018 – Dec 2020
B5: Month | C5: Orders | D5: Units Sold | E5: Revenue | F5: Profit | G5: Margin %
B6: 2018-05 | C6: =COUNTIF('Raw Data'!$Y$2:$Y$7992,$B6) -> 8 | D6: =SUMIF('Raw Data'!$Y$2:$Y$7992,$B6,'Raw Data'!$M$2:$M$7992) -> 39 | E6: =SUMIF('Raw Data'!$Y$2:$Y$7992,$B6,'Raw Data'!$Q$2:$Q$7992) -> 69636.283 | F6: =SUMIF('Raw Data'!$Y$2:$Y$7992,$B6,'Raw Data'!$S$2:$S$7992) -> 18271.112 | G6: =IFERROR(F6/E6,0) -> 0.26237921
B7: 2018-06 | C7: =COUNTIF('Raw Data'!$Y$2:$Y$7992,$B7) -> 252 | D7: =SUMIF('Raw Data'!$Y$2:$Y$7992,$B7,'Raw Data'!$M$2:$M$7992) -> 1112 | E7: =SUMIF('Raw Data'!$Y$2:$Y$7992,$B7,'Raw Data'!$Q$2:$Q$7992) -> 2180209.6 | F7: =SUMIF('Raw Data'!$Y$2:$Y$7992,$B7,'Raw Data'!$S$2:$S$7992) -> 629411.9 | G7: =IFERROR(F7/E7,0) -> 0.28869329
B8: 2018-07 | C8: =COUNTIF('Raw Data'!$Y$2:$Y$7992,$B8) -> 261 | D8: =SUMIF('Raw Data'!$Y$2:$Y$7992,$B8,'Raw Data'!$M$2:$M$7992) -> 1211 | E8: =SUMIF('Raw Data'!$Y$2:$Y$7992,$B8,'Raw Data'!$Q$2:$Q$7992) -> 2396750.8 | F8: =SUMIF('Raw Data'!$Y$2:$Y$7992,$B8,'Raw Data'!$S$2:$S$7992) -> 702408.16 | G8: =IFERROR(F8/E8,0) -> 0.29306683
B9: 2018-08 | C9: =COUNTIF('Raw Data'!$Y$2:$Y$7992,$B9) -> 279 | D9: =SUMIF('Raw Data'!$Y$2:$Y$7992,$B9,'Raw Data'!$M$2:$M$7992) -> 1266 | E9: =SUMIF('Raw Data'!$Y$2:$Y$7992,$B9,'Raw Data'!$Q$2:$Q$7992) -> 2563353.8 | F9: =SUMIF('Raw Data'!$Y$2:$Y$7992,$B9,'Raw Data'!$S$2:$S$7992) -> 730921.51 | G9: =IFERROR(F9/E9,0) -> 0.28514265
B10: 2018-09 | C10: =COUNTIF('Raw Data'!$Y$2:$Y$7992,$B10) -> 254 | D10: =SUMIF('Raw Data'!$Y$2:$Y$7992,$B10,'Raw Data'!$M$2:$M$7992) -> 1228 | E10: =SUMIF('Raw Data'!$Y$2:$Y$7992,$B10,'Raw Data'!$Q$2:$Q$7992) -> 2455740.8 | F10: =SUMIF('Raw Data'!$Y$2:$Y$7992,$B10,'Raw Data'!$S$2:$S$7992) -> 696348.45 | G10: =IFERROR(F10/E10,0) -> 0.28355943
B11: 2018-10 | C11: =COUNTIF('Raw Data'!$Y$2:$Y$7992,$B11) -> 228 | D11: =SUMIF('Raw Data'!$Y$2:$Y$7992,$B11,'Raw Data'!$M$2:$M$7992) -> 1072 | E11: =SUMIF('Raw Data'!$Y$2:$Y$7992,$B11,'Raw Data'!$Q$2:$Q$7992) -> 2062013.9 | F11: =SUMIF('Raw Data'!$Y$2:$Y$7992,$B11,'Raw Data'!$S$2:$S$7992) -> 603902.95 | G11: =IFERROR(F11/E11,0) -> 0.29287045
B12: 2018-11 | C12: =COUNTIF('Raw Data'!$Y$2:$Y$7992,$B12) -> 257 | D12: =SUMIF('Raw Data'!$Y$2:$Y$7992,$B12,'Raw Data'!$M$2:$M$7992) -> 1167 | E12: =SUMIF('Raw Data'!$Y$2:$Y$7992,$B12,'Raw Data'!$Q$2:$Q$7992) -> 2661493.8 | F12: =SUMIF('Raw Data'!$Y$2:$Y$7992,$B12,'Raw Data'!$S$2:$S$7992) -> 774184.36 | G12: =IFERROR(F12/E12,0) -> 0.2908834
B13: 2018-12 | C13: =COUNTIF('Raw Data'!$Y$2:$Y$7992,$B13) -> 297 | D13: =SUMIF('Raw Data'!$Y$2:$Y$7992,$B13,'Raw Data'!$M$2:$M$7992) -> 1387 | E13: =SUMIF('Raw Data'!$Y$2:$Y$7992,$B13,'Raw Data'!$Q$2:$Q$7992) -> 2713434 | F13: =SUMIF('Raw Data'!$Y$2:$Y$7992,$B13,'Raw Data'!$S$2:$S$7992) -> 791801.84 | G13: =IFERROR(F13/E13,0) -> 0.29180803
B14: 2019-01 | C14: =COUNTIF('Raw Data'!$Y$2:$Y$7992,$B14) -> 293 | D14: =SUMIF('Raw Data'!$Y$2:$Y$7992,$B14,'Raw Data'!$M$2:$M$7992) -> 1297 | E14: =SUMIF('Raw Data'!$Y$2:$Y$7992,$B14,'Raw Data'!$Q$2:$Q$7992) -> 2712820.6 | F14: =SUMIF('Raw Data'!$Y$2:$Y$7992,$B14,'Raw Data'!$S$2:$S$7992) -> 776917.81 | G14: =IFERROR(F14/E14,0) -> 0.28638746
B15: 2019-02 | C15: =COUNTIF('Raw Data'!$Y$2:$Y$7992,$B15) -> 232 | D15: =SUMIF('Raw Data'!$Y$2:$Y$7992,$B15,'Raw Data'!$M$2:$M$7992) -> 1014 | E15: =SUMIF('Raw Data'!$Y$2:$Y$7992,$B15,'Raw Data'!$Q$2:$Q$7992) -> 1940231.4 | F15: =SUMIF('Raw Data'!$Y$2:$Y$7992,$B15,'Raw Data'!$S$2:$S$7992) -> 600186.4 | G15: =IFERROR(F15/E15,0) -> 0.30933754
B16: 2019-03 | C16: =COUNTIF('Raw Data'!$Y$2:$Y$7992,$B16) -> 213 | D16: =SUMIF('Raw Data'!$Y$2:$Y$7992,$B16,'Raw Data'!$M$2:$M$7992) -> 944 | E16: =SUMIF('Raw Data'!$Y$2:$Y$7992,$B16,'Raw Data'!$Q$2:$Q$7992) -> 1936393.1 | F16: =SUMIF('Raw Data'!$Y$2:$Y$7992,$B16,'Raw Data'!$S$2:$S$7992) -> 575204.71 | G16: =IFERROR(F16/E16,0) -> 0.29704955
B17: 2019-04 | C17: =COUNTIF('Raw Data'!$Y$2:$Y$7992,$B17) -> 271 | D17: =SUMIF('Raw Data'!$Y$2:$Y$7992,$B17,'Raw Data'!$M$2:$M$7992) -> 1261 | E17: =SUMIF('Raw Data'!$Y$2:$Y$7992,$B17,'Raw Data'!$Q$2:$Q$7992) -> 2491884.6 | F17: =SUMIF('Raw Data'!$Y$2:$Y$7992,$B17,'Raw Data'!$S$2:$S$7992) -> 708709.96 | G17: =IFERROR(F17/E17,0) -> 0.28440722
... B37: 2020-12 | C37: =COUNTIF('Raw Data'!$Y$2:$Y$7992,$B37) -> 243 | D37: =SUMIF('Raw Data'!$Y$2:$Y$7992,$B37,'Raw Data'!$M$2:$M$7992) -> 1162 | E37: =SUMIF('Raw Data'!$Y$2:$Y$7992,$B37,'Raw Data'!$Q$2:$Q$7992) -> 2311083.9 | F37: =SUMIF('Raw Data'!$Y$2:$Y$7992,$B37,'Raw Data'!$S$2:$S$7992) -> 637228.84 | G37: =IFERROR(F37/E37,0) -> 0.27572726
